Workbook

Sheet Cover
A1: HELICAL PILE DESIGN -- EXCEL CALC SHEET
A4: Source
A5: Ported from the helical-pile-design Python calc engine (src/helical_pile_design/*.py). Every sheet maps 1:1 to the numbered step in the governing design procedure document, same as the source package's module structure.
A7: Pre-loaded example
A8: All input cells (pale yellow) are pre-filled with the 12 m pole / medium-stiff-clay worked example from tests/test_worked_example_12m.py -- change any yellow cell for a new project.
A10: Units
A11: SI internally throughout (m, kN, kN*m, kPa), matching the source package convention. No unit conversions are hidden inside formulas.
A13: Color key
A14: Pale YELLOW = editable input. Pale GREEN = key result. Pale ORANGE = assumption/limitation to confirm. GREEN/RED cell = pass/fail.
A16: Step 5b -- IMPORTANT
A17: The p-y lateral solver (Step 5b) is a nonlinear finite-difference beam-on-Winkler-foundation solve. It is implemented with native array formulas (MMULT/MINVERSE) -- no macros, and NO 'enable iterative calculation' setting is needed. The Python solver's fixed-point relaxation loop is unrolled into 25-45 sequential 'generation' blocks stacked down the sheet, each depending only on the PREVIOUS generation's result (a one-way chain, not a circular reference), so Excel computes it in one ordinary pass. An earlier design nested the matrix solve inside a true self-referencing circular loop; tested in real Excel via COM automation, it proved unreliable -- a transient error during the first iterative pass would latch permanently and never resolve, a known rough edge of combining array formulas with circular references. The unrolled design avoids that failure mode entirely. The mesh here is coarsened (21 nodes / 20 elements for service+strength, 11 nodes / 10 elements for the pushover sweep) vs. the Python reference's 180 elements, to keep the workbook a manageable size. This was verified against the Python engine directly: at 20 elements, groundline deflection tracks the 180-element reference within ~4%, and pushover lambda_ult within the design procedure's expected 9.5-10 band -- comfortably inside this suite's own regression tolerances (15-30%). Treat this sheet as a calibrated engineering approximation, not a bit-exact reproduction; for final sealed calculations, cross-check against the Python package.
A19: Two corrections vs. the source document
... A37: Pass/fail rollup -> Summary

Sheet 1-Loads
A1: STEP 1 -- LOAD DETERMINATION
A3: loads.py -- AASHTO LTS-6 wind pressure -> groundline V, M, P, Tz. Doc Section 1, eq. 1.1-1.4.
A5: Pole geometry (A1-A3)
A6: Pole height, h | D6: 12 | E6: m
A7: Base diameter, b_base | D7: 0.25 | E7: m
A8: Top diameter, b_top | D8: 0.1 | E8: m
A9: Pole+arm projected area, A_pole | D9: 2.1 | E9: m^2
A10: Pole+arm weight | D10: 1.5 | E10: kN
A11: Drag coefficient, Cd (round tapered) | D11: 0.5 | E11: -
A13: Luminaire (A4-A5)
A14: Luminaire EPA (includes Cd) | D14: 0.5 | E14: m^2
A15: Luminaire weight | D15: 0.25 | E15: kN
A16: Mast-arm eccentricity, e_arm | D16: 0 | E16: m
A18: Wind environment -- strength case (A6-A7)
A19: Basic wind speed, V (3-s gust, strength) | D19: 51.4 | E19: m/s
A20: Kz at luminaire height | D20: 1.04 | E20: -
A21: Kz at pole area centroid | D21: 1 | E21: -
A22: Directionality, Kd | D22: 0.95 | E22: -
A23: Gust factor, G | D23: 1.14 | E23: -
A24: Service/strength pressure ratio (~10-yr MRI) | D24: 0.44 | E24: -
A26: Load combination factors
A27: Reveal (rigid riser above grade) | D27: 0 | E27: m
A28: Dead load factor | D28: 1 | E28: -
A29: Wind load factor | D29: 1 | E29: -
A31: Calculated -- Strength case (Extreme I)
A32: eq. 1.1: Pz = 0.613*Kz*Kd*G*V^2 [Pa]->kPa. eq. 1.2: z_bar = (h/3)(b_base+2b_top)/(b_base+b_top).
A33: Centroid height, z_bar | D33: =($D$6/3)*($D$7+2*$D$8)/($D$7+$D$8) | E33: m
A34: Design pressure at z_bar, Pz(z_bar) | D34: =0.613*$D$21*$D$22*$D$23*$D$19^2/1000 | E34: kPa
A35: Design pressure at h, Pz(h) | D35: =0.613*$D$20*$D$22*$D$23*$D$19^2/1000 | E35: kPa
A36: Pole+arm wind force, F_pole | D36: =$D$34*$D$11*$D$9 | E36: kN
A37: Luminaire wind force, F_lum | D37: =$D$35*$D$14 | E37: kN
A38: Groundline shear, V | D38: =$D$29*($D$36+$D$37) | E38: kN
A39: Groundline moment, M | D39: =$D$29*($D$36*$D$33+$D$37*$D$6)+$D$38*$D$27 | E39: kN*m
A40: Groundline axial, P | D40: =$D$28*($D$10+$D$15) | E40: kN
A41: Groundline torsion, Tz | D41: =$D$29*$D$37*$D$16 | E41: kN*m
A42: Load eccentricity, e = M/V | D42: =IF($D$38<>0,$D$39/$D$38,"inf") | E42: m
A44: Calculated -- Service case (~10-yr MRI)
A45: eq. 1.4 note: V_service = V_strength * SQRT(service_pressure_ratio) (Pz ~ V^2).
A46: Service wind speed, V_service | D46: =$D$19*SQRT($D$24) | E46: m/s
A47: Service pressure at z_bar | D47: =0.613*$D$21*$D$22*$D$23*$D$46^2/1000 | E47: kPa
...

Sheet 2-Geotech
A1: STEP 2 -- GEOTECHNICAL PARAMETERIZATION
A3: geotech.py -- SPT/CPT correlations -> design soil profile. Doc Section 2.
A5: Reference correlations (informational -- prefer lab/CPT for design Su)
A6: SPT N60 (blows/ft), if available | D6: 17 | E6: -
A7: Su from N60 = 6*N60 (eq. 2.1) | D7: =6*$D$6 | E7: kPa
A8: CPT qt, if available | D8: 0 | E8: kPa
A9: In-situ sigma'v0 at CPT depth | D9: 0 | E9: kPa
A10: CPT Nkt (12-16) | D10: 14 | E10: -
A11: Su from CPT (eq. 2.1) | D11: =IF($D$10=0,"n/a",($D$8-$D$9)/$D$10) | E11: kPa
A12: phi' from N60, Peck/Hanson (eq. 2.2, sand only) | D12: =27.1+0.3*$D$6-0.00054*$D$6^2 | E12: deg
A14: Design soil profile (governing clay layer within lateral influence zone)
A15: Design Su (governing layer) | D15: 50 | E15: kPa
A16: Basis | D16: lab UU/CU
A17: eps50 correlation vs. Su (reference, eq. 2.1) | D17: =IF($D$15<25,0.02,IF($D$15<=50,0.01,0.007)) | E17: -
A18: Design eps50 (override -- engineering judgment) | D18: 0.007 | E18: -
A19: NOTE: Doc worked example uses eps50=0.007 explicitly (stiff-clay band), overriding the raw Su=50 correlation boundary value of 0.01 -- confirm against site data.
A20: Total unit weight, gamma (above GWT) | D20: 18.5 | E20: kN/m^3
A21: Unit weight of water, gamma_w | D21: 9.81 | E21: kN/m^3
A22: Submerged unit weight, gamma_sub (below GWT) | D22: =$D$20-$D$21 | E22: kN/m^3
A23: Groundwater depth, GWT | D23: 3 | E23: m
A24: Frost depth, d_f | D24: 1.2 | E24: m
A26: Step 10 QA/QC trigger flag
A27: p-y params from lab/CPT (not SPT-only)? | D27: =IF($D$16<>"SPT correlation",TRUE,FALSE)

Sheet 3-Sizing
A1: STEP 3 -- PRELIMINARY PILE SIZING
A3: sizing.py -- trial shaft/helix geometry + embedment screens. Doc Section 3.
A5: Trial shaft diameter
A6: Corrected heuristic (see sizing.py docstring): doc's own Section 3.1 coefficient (40) is dimensionally inconsistent (gives 0.71 m, outside its own stated 168-324 mm typical range). D_shaft >= SQRT(Mu/320) used here instead, calibrated to the stated range -- a rough starting point only, refined by Steps 4-6.
A7: Design moment, Mu (from Step 1 strength case) | D7: ='1-Loads'!$D$39 | E7: kN*m
A8: Required D_shaft (heuristic) | D8: =SQRT(MAX($D$7,0)/320) | E8: m
A9: Nearest standard OD (168/219/273/324 mm) | D9: =IF($D$8<=0.168,0.168,IF($D$8<=0.219,0.219,IF($D$8<=0.273,0.273,0.324))) | E9: m
A10: Selected shaft OD, D_shaft | D10: 0.273 | E10: m
A11: Nominal wall thickness, t_nominal | D11: 9.3 | E11: mm
A13: Trial helix configuration (doc Section 3.2)
A14: Up to 3 helices supported. Leave diameter/depth blank for an unused plate.
A15: Helix # | D15: Diameter, D_h (m) | E15: Depth, z (m)
A16: Helix 1 | D16: 0.45 | E16: 3
A17: Helix 2 | D17: 0.45 | E17: 4.35
A18: Helix 3
A19: Helix pitch | D19: 0.075 | E19: m
A20: Shaft standoff below bottom helix | D20: 0.15 | E20: m
A22: Embedment (doc Section 3.3)
A23: Top helix depth | D23: =MIN($E$16:$E$18) | E23: m
A24: Bottom helix depth | D24: =MAX($E$16:$E$18) | E24: m
A25: Pile tip depth, L | D25: =$D$24+$D$20 | E25: m
A26: Top helix diameter, D_h,top | D26: {=INDEX($D$16:$D$18,MATCH($D$23,$E$16:$E$18,0))} | E26: m
A27: Frost-clearance requirement (top >= d_f+3*D_h) | D27: ='2-Geotech'!$D$24+3*$D$26 | E27: m
A28: Frost clearance OK? | D28: =$D$23>=$D$27
A29: 'Deep foundation' requirement (top >= 5*D_h) | D29: =5*$D$26 | E29: m
A30: Deep-foundation mode OK? | D30: =$D$23>=$D$29
A31: L / D_shaft (informational -- verify vs. Step 5 required length) | D31: =$D$25/$D$10 | E31: -
A32: Step 3 embedment screens -- ALL PASS? | D32: =AND($D$28,$D$30)

Sheet 4-Axial
A1: STEP 4 -- AXIAL CAPACITY (COMPRESSION & TENSION)
A3: axial.py -- individual bearing + cylindrical shear (lesser governs); frost-uplift demand. Doc Section 4. FS_required = 2.0.
A5: Shared inputs
A6: Shaft OD, D_shaft (Step 3) | D6: ='3-Sizing'!$D$10 | E6: m
A7: Design Su (Step 2) | D7: ='2-Geotech'!$D$15 | E7: kPa
A8: Effective shaft-adhesion length, L_eff (frost zone to top helix, doc-specific) | D8: 1.35 | E8: m
A9: NOTE: L_eff is a caller-supplied parameter in axial.py (not auto-derived from helix depth) -- the worked example's 1.35 m reflects the doc's specific adhesion-zone definition; confirm against project geometry rather than assuming L_eff = top-helix-depth minus d_f.
A10: alpha (API linear-ramp correlation, reference) | D10: =IF($D$7<=25,1,IF($D$7>=70,0.5,1+($D$7-25)*(0.5-1)/(70-25))) | E10: -
A11: Alpha override (blank cell -> use correlation above) | D11: 0.5 | E11: -
A12: Alpha used | D12: =IF($D$11="",IF($D$7<=25,1,IF($D$7>=70,0.5,1+($D$7-25)*(0.5-1)/(70-25))),$D$11) | E12: -
A14: 4.1 Individual bearing method (clay)
A15: Qu = sum(A_h,i * 9*Su) + alpha*Su*pi*D_shaft*L_eff. A_h = pi/4*(D_h^2-D_shaft^2). eq. 4.1.
A16: Helix 1 net area, A_h | D16: =IF('3-Sizing'!$D$16="",0,PI()/4*('3-Sizing'!$D$16^2-$D$6^2)) | E16: m^2
A17: Helix 1 bearing = A_h*9*Su | D17: =$D$16*9*$D$7 | E17: kN
A18: Helix 2 net area, A_h | D18: =IF('3-Sizing'!$D$17="",0,PI()/4*('3-Sizing'!$D$17^2-$D$6^2)) | E18: m^2
A19: Helix 2 bearing = A_h*9*Su | D19: =$D$18*9*$D$7 | E19: kN
A20: Helix 3 net area, A_h | D20: =IF('3-Sizing'!$D$18="",0,PI()/4*('3-Sizing'!$D$18^2-$D$6^2)) | E20: m^2
A21: Helix 3 bearing = A_h*9*Su | D21: =$D$20*9*$D$7 | E21: kN
A22: Shaft adhesion term = alpha*Su*pi*D_shaft*L_eff | D22: =$D$12*$D$7*PI()*$D$6*$D$8 | E22: kN
A23: Qu, individual bearing (compression) | D23: =($D$17+$D$19+$D$21)+$D$22 | E23: kN
A25: 4.2 Cylindrical shear method
A26: Qu = A_h,bottom*9*Su + Su*pi*D_h,avg*L_c + alpha*Su*pi*D_shaft*L_eff. Governs when helices are closely spaced. eq. 4.2.
A27: Bottom helix diameter, D_h,bottom | D27: {=INDEX('3-Sizing'!$D$16:$D$18,MATCH('3-Sizing'!$D$24,'3-Sizing'!$E$16:$E$18,0))} | E27: m
A28: Average helix diameter, D_h,avg | D28: =AVERAGE('3-Sizing'!$D$16:$D$18) | E28: m
A29: Cylinder length between helices, L_c | D29: ='3-Sizing'!$D$24-'3-Sizing'!$D$23 | E29: m
A30: Bottom-helix bearing | D30: =PI()/4*($D$27^2-$D$6^2)*9*$D$7 | E30: kN
A31: Cylinder shear | D31: =$D$7*PI()*$D$28*$D$29 | E31: kN
A32: Qu, cylindrical shear (compression) | D32: =$D$30+$D$31+$D$22 | E32: kN
A34: 4.3 Frost-heave uplift demand
A35: T_frost = tau_ad * pi * D_shaft * d_f. eq. 4.3.
A36: Adfreeze bond stress, tau_ad [ASSUMED -- validate] | D36: 20 | E36: kPa
A37: Frost-uplift demand, T_frost | D37: =$D$36*PI()*$D$6*'2-Geotech'!$D$24 | E37: kN
A39: 4.1 Uplift (tension) resistance
A40: Tu = sum(A_h,i*9*Su) [+ optional shaft adhesion below d_f].
A41: Tu, individual bearing (tension, helix only) | D41: =($D$17+$D$19+$D$21) | E41: kN
A42: Tu, cylindrical-shear tension [not defined by source module -- enter separately if a project-specific method applies, else leave = Tu,individual] | E42: kN
A43: Tu, cylindrical (used) | D43: =IF($D$42="",$D$41,$D$42) | E43: kN
A45: 4.4 Acceptance -- FS_required = 2.0
A46: Axial demand override, P_max (compression) [doc worked value includes adapter hardware + 1.25 DL factor not modeled in Step 1] | D46: 2.6 | E46: kN
A47: (for reference: Step 1 P_strength) | D47: ='1-Loads'!$D$40 | E47: kN
...

Sheet 5a-Broms
A1: STEP 5a -- BROMS METHOD (PRELIMINARY LATERAL CHECK)
A3: lateral_py.broms_ultimate_clay_kN -- free-head short rigid pile in clay. Doc eq. 5.2. FS_required = 2.0.
A5: Inputs (linked)
A6: Su | D6: ='2-Geotech'!$D$15 | E6: kPa
A7: D_shaft | D7: ='3-Sizing'!$D$10 | E7: m
A8: Embedded length, L (pile tip depth) | D8: ='3-Sizing'!$D$25 | E8: m
A9: Load eccentricity, e = M/V (Step 1 strength) | D9: ='1-Loads'!$D$42 | E9: m
A10: Frost depth, d_f | D10: ='2-Geotech'!$D$24 | E10: m
A11: Design shear demand, V (Step 1 strength) | D11: ='1-Loads'!$D$38 | E11: kN
A13: Closure-equation setup
A14: z0 = MAX(1.5*D_shaft, d_f). Available length must satisfy L = z0 + f + g.
A15: Exclusion depth, z0 | D15: =MAX(1.5*$D$7,$D$10) | E15: m
A16: Available length, avail = L - z0 | D16: =$D$8-$D$15 | E16: m
A17: NOTE: If 'avail' <= 0, the embedded length does not clear the exclusion depth -- lengthen the pile before proceeding (matches the ValueError raised by broms_ultimate_clay_kN in the source module).
A19: Bisection solve for Hu (closure equation g(Hu) = f + g - avail = 0)
A20: f = Hu/(9*Su*D_shaft). Mmax = Hu*(e+z0+0.5f). g = SQRT(MAX(Mmax,0)/(2.25*Su*D_shaft)). 60-step bisection ladder -- plain formulas, no circular references, no macros.
B21: iter | C21: lo (kN) | D21: hi (kN) | E21: mid = Hu trial | F21: f | G21: Mmax | H21: g | I21: g(Hu)=f+g-avail
B22: 1 | C22: 1e-06 | D22: 100000 | E22: =($C$22+$D$22)/2 | F22: =$E$22/(9*$D$6*$D$7) | G22: =$E$22*($D$9+$D$15+0.5*$F$22) | H22: =SQRT(MAX($G$22,0)/(2.25*$D$6*$D$7)) | I22: =$F$22+$H$22-$D$16
B23: 2 | C23: =IF($I$22>0,$C$22,$E$22) | D23: =IF($I$22>0,$E$22,$D$22) | E23: =($C$23+$D$23)/2 | F23: =$E$23/(9*$D$6*$D$7) | G23: =$E$23*($D$9+$D$15+0.5*$F$23) | H23: =SQRT(MAX($G$23,0)/(2.25*$D$6*$D$7)) | I23: =$F$23+$H$23-$D$16
B24: 3 | C24: =IF($I$23>0,$C$23,$E$23) | D24: =IF($I$23>0,$E$23,$D$23) | E24: =($C$24+$D$24)/2 | F24: =$E$24/(9*$D$6*$D$7) | G24: =$E$24*($D$9+$D$15+0.5*$F$24) | H24: =SQRT(MAX($G$24,0)/(2.25*$D$6*$D$7)) | I24: =$F$24+$H$24-$D$16
B25: 4 | C25: =IF($I$24>0,$C$24,$E$24) | D25: =IF($I$24>0,$E$24,$D$24) | E25: =($C$25+$D$25)/2 | F25: =$E$25/(9*$D$6*$D$7) | G25: =$E$25*($D$9+$D$15+0.5*$F$25) | H25: =SQRT(MAX($G$25,0)/(2.25*$D$6*$D$7)) | I25: =$F$25+$H$25-$D$16
B26: 5 | C26: =IF($I$25>0,$C$25,$E$25) | D26: =IF($I$25>0,$E$25,$D$25) | E26: =($C$26+$D$26)/2 | F26: =$E$26/(9*$D$6*$D$7) | G26: =$E$26*($D$9+$D$15+0.5*$F$26) | H26: =SQRT(MAX($G$26,0)/(2.25*$D$6*$D$7)) | I26: =$F$26+$H$26-$D$16
B27: 6 | C27: =IF($I$26>0,$C$26,$E$26) | D27: =IF($I$26>0,$E$26,$D$26) | E27: =($C$27+$D$27)/2 | F27: =$E$27/(9*$D$6*$D$7) | G27: =$E$27*($D$9+$D$15+0.5*$F$27) | H27: =SQRT(MAX($G$27,0)/(2.25*$D$6*$D$7)) | I27: =$F$27+$H$27-$D$16
B28: 7 | C28: =IF($I$27>0,$C$27,$E$27) | D28: =IF($I$27>0,$E$27,$D$27) | E28: =($C$28+$D$28)/2 | F28: =$E$28/(9*$D$6*$D$7) | G28: =$E$28*($D$9+$D$15+0.5*$F$28) | H28: =SQRT(MAX($G$28,0)/(2.25*$D$6*$D$7)) | I28: =$F$28+$H$28-$D$16
B29: 8 | C29: =IF($I$28>0,$C$28,$E$28) | D29: =IF($I$28>0,$E$28,$D$28) | E29: =($C$29+$D$29)/2 | F29: =$E$29/(9*$D$6*$D$7) | G29: =$E$29*($D$9+$D$15+0.5*$F$29) | H29: =SQRT(MAX($G$29,0)/(2.25*$D$6*$D$7)) | I29: =$F$29+$H$29-$D$16
B30: 9 | C30: =IF($I$29>0,$C$29,$E$29) | D30: =IF($I$29>0,$E$29,$D$29) | E30: =($C$30+$D$30)/2 | F30: =$E$30/(9*$D$6*$D$7) | G30: =$E$30*($D$9+$D$15+0.5*$F$30) | H30: =SQRT(MAX($G$30,0)/(2.25*$D$6*$D$7)) | I30: =$F$30+$H$30-$D$16
B31: 10 | C31: =IF($I$30>0,$C$30,$E$30) | D31: =IF($I$30>0,$E$30,$D$30) | E31: =($C$31+$D$31)/2 | F31: =$E$31/(9*$D$6*$D$7) | G31: =$E$31*($D$9+$D$15+0.5*$F$31) | H31: =SQRT(MAX($G$31,0)/(2.25*$D$6*$D$7)) | I31: =$F$31+$H$31-$D$16
B32: 11 | C32: =IF($I$31>0,$C$31,$E$31) | D32: =IF($I$31>0,$E$31,$D$31) | E32: =($C$32+$D$32)/2 | F32: =$E$32/(9*$D$6*$D$7) | G32: =$E$32*($D$9+$D$15+0.5*$F$32) | H32: =SQRT(MAX($G$32,0)/(2.25*$D$6*$D$7)) | I32: =$F$32+$H$32-$D$16
B33: 12 | C33: =IF($I$32>0,$C$32,$E$32) | D33: =IF($I$32>0,$E$32,$D$32) | E33: =($C$33+$D$33)/2 | F33: =$E$33/(9*$D$6*$D$7) | G33: =$E$33*($D$9+$D$15+0.5*$F$33) | H33: =SQRT(MAX($G$33,0)/(2.25*$D$6*$D$7)) | I33: =$F$33+$H$33-$D$16
B34: 13 | C34: =IF($I$33>0,$C$33,$E$33) | D34: =IF($I$33>0,$E$33,$D$33) | E34: =($C$34+$D$34)/2 | F34: =$E$34/(9*$D$6*$D$7) | G34: =$E$34*($D$9+$D$15+0.5*$F$34) | H34: =SQRT(MAX($G$34,0)/(2.25*$D$6*$D$7)) | I34: =$F$34+$H$34-$D$16
B35: 14 | C35: =IF($I$34>0,$C$34,$E$34) | D35: =IF($I$34>0,$E$34,$D$34) | E35: =($C$35+$D$35)/2 | F35: =$E$35/(9*$D$6*$D$7) | G35: =$E$35*($D$9+$D$15+0.5*$F$35) | H35: =SQRT(MAX($G$35,0)/(2.25*$D$6*$D$7)) | I35: =$F$35+$H$35-$D$16
B36: 15 | C36: =IF($I$35>0,$C$35,$E$35) | D36: =IF($I$35>0,$E$35,$D$35) | E36: =($C$36+$D$36)/2 | F36: =$E$36/(9*$D$6*$D$7) | G36: =$E$36*($D$9+$D$15+0.5*$F$36) | H36: =SQRT(MAX($G$36,0)/(2.25*$D$6*$D$7)) | I36: =$F$36+$H$36-$D$16
B37: 16 | C37: =IF($I$36>0,$C$36,$E$36) | D37: =IF($I$36>0,$E$36,$D$36) | E37: =($C$37+$D$37)/2 | F37: =$E$37/(9*$D$6*$D$7) | G37: =$E$37*($D$9+$D$15+0.5*$F$37) | H37: =SQRT(MAX($G$37,0)/(2.25*$D$6*$D$7)) | I37: =$F$37+$H$37-$D$16
B38: 17 | C38: =IF($I$37>0,$C$37,$E$37) | D38: =IF($I$37>0,$E$37,$D$37) | E38: =($C$38+$D$38)/2 | F38: =$E$38/(9*$D$6*$D$7) | G38: =$E$38*($D$9+$D$15+0.5*$F$38) | H38: =SQRT(MAX($G$38,0)/(2.25*$D$6*$D$7)) | I38: =$F$38+$H$38-$D$16
B39: 18 | C39: =IF($I$38>0,$C$38,$E$38) | D39: =IF($I$38>0,$E$38,$D$38) | E39: =($C$39+$D$39)/2 | F39: =$E$39/(9*$D$6*$D$7) | G39: =$E$39*($D$9+$D$15+0.5*$F$39) | H39: =SQRT(MAX($G$39,0)/(2.25*$D$6*$D$7)) | I39: =$F$39+$H$39-$D$16
B40: 19 | C40: =IF($I$39>0,$C$39,$E$39) | D40: =IF($I$39>0,$E$39,$D$39) | E40: =($C$40+$D$40)/2 | F40: =$E$40/(9*$D$6*$D$7) | G40: =$E$40*($D$9+$D$15+0.5*$F$40) | H40: =SQRT(MAX($G$40,0)/(2.25*$D$6*$D$7)) | I40: =$F$40+$H$40-$D$16
B41: 20 | C41: =IF($I$40>0,$C$40,$E$40) | D41: =IF($I$40>0,$E$40,$D$40) | E41: =($C$41+$D$41)/2 | F41: =$E$41/(9*$D$6*$D$7) | G41: =$E$41*($D$9+$D$15+0.5*$F$41) | H41: =SQRT(MAX($G$41,0)/(2.25*$D$6*$D$7)) | I41: =$F$41+$H$41-$D$16
B42: 21 | C42: =IF($I$41>0,$C$41,$E$41) | D42: =IF($I$41>0,$E$41,$D$41) | E42: =($C$42+$D$42)/2 | F42: =$E$42/(9*$D$6*$D$7) | G42: =$E$42*($D$9+$D$15+0.5*$F$42) | H42: =SQRT(MAX($G$42,0)/(2.25*$D$6*$D$7)) | I42: =$F$42+$H$42-$D$16
B43: 22 | C43: =IF($I$42>0,$C$42,$E$42) | D43: =IF($I$42>0,$E$42,$D$42) | E43: =($C$43+$D$43)/2 | F43: =$E$43/(9*$D$6*$D$7) | G43: =$E$43*($D$9+$D$15+0.5*$F$43) | H43: =SQRT(MAX($G$43,0)/(2.25*$D$6*$D$7)) | I43: =$F$43+$H$43-$D$16
B44: 23 | C44: =IF($I$43>0,$C$43,$E$43) | D44: =IF($I$43>0,$E$43,$D$43) | E44: =($C$44+$D$44)/2 | F44: =$E$44/(9*$D$6*$D$7) | G44: =$E$44*($D$9+$D$15+0.5*$F$44) | H44: =SQRT(MAX($G$44,0)/(2.25*$D$6*$D$7)) | I44: =$F$44+$H$44-$D$16
...

Sheet 5b-pySolver
A1: STEP 5b -- p-y METHOD (FINAL LATERAL/MOMENT CHECK)
A3: lateral_py.solve_py / pushover -- nonlinear beam-on-Matlock-soft-clay-Winkler-foundation. Doc Section 5.3.
A4: NOTE: No macros and no 'iterative calculation' setting needed. The Python solver's fixed-point relaxation loop is unrolled into sequential 'generation' blocks stacked down this sheet -- each generation's matrix solve depends only on the PREVIOUS generation's result, a one-way chain, not a circular reference. (An earlier version nested the matrix solve in a true self-referencing loop; tested in real Excel via COM automation, it was unreliable -- a transient error during the first iterative pass would latch permanently. This design avoids that failure mode entirely.) See the Cover sheet for the mesh-coarsening accuracy note.
A6: SERVICE CASE (n=20 elements, 25 unrolled iterations) -- eq. 5.3, serviceability check
A8: V (kN) | B8: ='1-Loads'!$D$51 | C8: kN
A9: M (kN*m) | B9: =-'1-Loads'!$D$52 | C9: kN*m
A10: D_shaft | B10: ='3-Sizing'!$D$10 | C10: m
A11: t (corroded) | B11: ='7-Corrosion'!$D$19/1000 | C11: m
A12: E, steel | B12: =200000000 | C12: kPa
A13: I (pipe) | B13: =PI()/64*($B$10^4-($B$10-2*$B$11)^4) | C13: m^4
A14: EI | B14: =$B$12*$B$13 | C14: kN*m^2
A15: L, embedded length | B15: ='3-Sizing'!$D$25 | C15: m
A16: n_elements | B16: 20 | C16: -
A17: h = L/n | B17: =$B$15/$B$16 | C17: m
A18: a = 12EI/h^3 | B18: =12*$B$14/$B$17^3
A19: b = 6EI/h^2 | B19: =6*$B$14/$B$17^2
A20: c = 4EI/h | B20: =4*$B$14/$B$17
A21: d = 2EI/h | B21: =2*$B$14/$B$17
A22: Su | B22: ='2-Geotech'!$D$15 | C22: kPa
A23: gamma | B23: ='2-Geotech'!$D$20 | C23: kN/m3
A24: gamma_sub | B24: ='2-Geotech'!$D$22 | C24: kN/m3
A25: GWT depth | B25: ='2-Geotech'!$D$23 | C25: m
A26: eps50 | B26: ='2-Geotech'!$D$18 | C26: -
A27: frost depth | B27: ='2-Geotech'!$D$24 | C27: m
A28: J (Matlock) | B28: 0.5 | C28: -
A29: y50 = 2.5*eps50*D | B29: =2.5*$B$26*$B$10 | C29: m
A30: n_generations (unrolled iterations) | B30: 25 | C30: -
D32: i | E32: z (m) | F32: sigma_v (kPa) | G32: Np | H32: pu (kN/m) | I32: trib (m)
D33: 0 | E33: =$D$33*$B$17 | F33: =IF($E$33<=$B$25,$B$23*$E$33,$B$23*$B$25+$B$24*($E$33-$B$25)) | G33: =MIN(3+$F$33/$B$22+$B$28*$E$33/$B$10,9) | H33: =$G$33*$B$22*$B$10 | I33: =IF(OR($D$33=0,$D$33=$B$16),$B$17/2,$B$17)
D34: 1 | E34: =$D$34*$B$17 | F34: =IF($E$34<=$B$25,$B$23*$E$34,$B$23*$B$25+$B$24*($E$34-$B$25)) | G34: =MIN(3+$F$34/$B$22+$B$28*$E$34/$B$10,9) | H34: =$G$34*$B$22*$B$10 | I34: =IF(OR($D$34=0,$D$34=$B$16),$B$17/2,$B$17)
D35: 2 | E35: =$D$35*$B$17 | F35: =IF($E$35<=$B$25,$B$23*$E$35,$B$23*$B$25+$B$24*($E$35-$B$25)) | G35: =MIN(3+$F$35/$B$22+$B$28*$E$35/$B$10,9) | H35: =$G$35*$B$22*$B$10 | I35: =IF(OR($D$35=0,$D$35=$B$16),$B$17/2,$B$17)
D36: 3 | E36: =$D$36*$B$17 | F36: =IF($E$36<=$B$25,$B$23*$E$36,$B$23*$B$25+$B$24*($E$36-$B$25)) | G36: =MIN(3+$F$36/$B$22+$B$28*$E$36/$B$10,9) | H36: =$G$36*$B$22*$B$10 | I36: =IF(OR($D$36=0,$D$36=$B$16),$B$17/2,$B$17)
D37: 4 | E37: =$D$37*$B$17 | F37: =IF($E$37<=$B$25,$B$23*$E$37,$B$23*$B$25+$B$24*($E$37-$B$25)) | G37: =MIN(3+$F$37/$B$22+$B$28*$E$37/$B$10,9) | H37: =$G$37*$B$22*$B$10 | I37: =IF(OR($D$37=0,$D$37=$B$16),$B$17/2,$B$17)
D38: 5 | E38: =$D$38*$B$17 | F38: =IF($E$38<=$B$25,$B$23*$E$38,$B$23*$B$25+$B$24*($E$38-$B$25)) | G38: =MIN(3+$F$38/$B$22+$B$28*$E$38/$B$10,9) | H38: =$G$38*$B$22*$B$10 | I38: =IF(OR($D$38=0,$D$38=$B$16),$B$17/2,$B$17)
D39: 6 | E39: =$D$39*$B$17 | F39: =IF($E$39<=$B$25,$B$23*$E$39,$B$23*$B$25+$B$24*($E$39-$B$25)) | G39: =MIN(3+$F$39/$B$22+$B$28*$E$39/$B$10,9) | H39: =$G$39*$B$22*$B$10 | I39: =IF(OR($D$39=0,$D$39=$B$16),$B$17/2,$B$17)
D40: 7 | E40: =$D$40*$B$17 | F40: =IF($E$40<=$B$25,$B$23*$E$40,$B$23*$B$25+$B$24*($E$40-$B$25)) | G40: =MIN(3+$F$40/$B$22+$B$28*$E$40/$B$10,9) | H40: =$G$40*$B$22*$B$10 | I40: =IF(OR($D$40=0,$D$40=$B$16),$B$17/2,$B$17)
D41: 8 | E41: =$D$41*$B$17 | F41: =IF($E$41<=$B$25,$B$23*$E$41,$B$23*$B$25+$B$24*($E$41-$B$25)) | G41: =MIN(3+$F$41/$B$22+$B$28*$E$41/$B$10,9) | H41: =$G$41*$B$22*$B$10 | I41: =IF(OR($D$41=0,$D$41=$B$16),$B$17/2,$B$17)
D42: 9 | E42: =$D$42*$B$17 | F42: =IF($E$42<=$B$25,$B$23*$E$42,$B$23*$B$25+$B$24*($E$42-$B$25)) | G42: =MIN(3+$F$42/$B$22+$B$28*$E$42/$B$10,9) | H42: =$G$42*$B$22*$B$10 | I42: =IF(OR($D$42=0,$D$42=$B$16),$B$17/2,$B$17)
D43: 10 | E43: =$D$43*$B$17 | F43: =IF($E$43<=$B$25,$B$23*$E$43,$B$23*$B$25+$B$24*($E$43-$B$25)) | G43: =MIN(3+$F$43/$B$22+$B$28*$E$43/$B$10,9) | H43: =$G$43*$B$22*$B$10 | I43: =IF(OR($D$43=0,$D$43=$B$16),$B$17/2,$B$17)
D44: 11 | E44: =$D$44*$B$17 | F44: =IF($E$44<=$B$25,$B$23*$E$44,$B$23*$B$25+$B$24*($E$44-$B$25)) | G44: =MIN(3+$F$44/$B$22+$B$28*$E$44/$B$10,9) | H44: =$G$44*$B$22*$B$10 | I44: =IF(OR($D$44=0,$D$44=$B$16),$B$17/2,$B$17)
...

Sheet 6-Structural
A1: STEP 6 -- SHAFT STRUCTURAL CHECKS (AISC 360, CORRODED SECTION)
A3: structural.py -- section compactness, H1 combined axial+flexure, shear, buckling trigger, torsion cap. Doc Section 6. Uses t_corroded (Step 7), never nominal.
A5: Section properties -- doc eq. 6.1
A6: Shaft OD, D (Step 3) | D6: ='3-Sizing'!$D$10 | E6: m
A7: Corroded wall, t_c (Step 7) | D7: ='7-Corrosion'!$D$19/1000 | E7: m
A8: Steel yield strength, Fy | D8: 345000 | E8: kPa
A9: Elastic modulus, E | D9: 200000000 | E9: kPa
A10: Inner diameter, d_i = D - 2*t_c | D10: =$D$6-2*$D$7 | E10: m
A11: Elastic section modulus, S | D11: =PI()/32*($D$6^4-$D$10^4)/$D$6 | E11: m^3
A12: Plastic section modulus, Z | D12: =($D$6^3-$D$10^3)/6 | E12: m^3
A13: Area, A | D13: =PI()/4*($D$6^2-$D$10^2) | E13: m^2
A14: Slenderness, D/t_c | D14: =$D$6/$D$7 | E14: -
A15: Compactness limit, 0.07*E/Fy (AISC Table B4.1b) | D15: =0.07*$D$9/$D$8 | E15: -
A16: Section compact? | D16: =$D$14<=$D$15
A18: H1 combined axial + flexure -- doc eq. 6.2
A19: phi_c (compression) | D19: 0.9 | E19: -
A20: phi_b (flexure) | D20: 0.9 | E20: -
A21: Axial demand, Pr (Step 1 strength P) | D21: ='1-Loads'!$D$40 | E21: kN
A22: Flexural demand, Mr (Step 5b strength M_max) | D22: ='5b-pySolver'!$B$3589 | E22: kN*m
A23: Pc = phi_c*Fy*A | D23: =$D$19*$D$8*$D$13 | E23: kN
A24: Mc = phi_b*Fy*Z | D24: =$D$20*$D$8*$D$12 | E24: kN*m
A25: Pr/Pc | D25: =$D$21/$D$23 | E25: -
A26: Mr/Mc | D26: =$D$22/$D$24 | E26: -
A27: Governing equation | D27: =IF($D$25>=0.2,"H1-1a","H1-1b") | E27: -
A28: Interaction ratio | D28: =IF($D$25>=0.2,$D$25+(8/9)*$D$26,$D$25/2+$D$26) | E28: -
A29: H1 interaction passes (ratio<=1.0)? | D29: =$D$28<=1
A31: Shear -- doc Section 6.2 (trivially satisfied for light poles, checked anyway)
A32: phi_v (shear) | D32: 0.9 | E32: -
A33: Shear demand, Vu (Step 1 strength V) | D33: ='1-Loads'!$D$38 | E33: kN
A34: Vn = 0.6*Fy*(A/2) | D34: =0.6*$D$8*($D$13/2) | E34: kN
A35: Shear passes? | D35: =$D$33<=$D$32*$D$34
A37: Column-buckling trigger -- doc Section 6.3 (advisory; run a separate Pn check if triggered)
A38: Su (Step 2) | D38: ='2-Geotech'!$D$15 | E38: kPa
A39: Continuous weak layer thickness through which pile passes | D39: 4.5 | E39: m
A40: Shaft exposed or scoured? | D40: No
A41: Buckling check triggered? (TRUE = perform separate Pn check) | D41: =IF($D$40="Yes",TRUE,IF(AND($D$39>=1.5,$D$38<25),TRUE,FALSE))
A43: Installation torsion cap -- doc eq. 6.4
A44: phi_T | D44: 0.9 | E44: -
A45: T_install_max (Step 9 T_avg) | D45: ='9-Torque'!$D$12 | E45: kN*m
A46: T_rated (Step 9) | D46: ='9-Torque'!$D$11 | E46: kN*m
...

Sheet 7-Corrosion
A1: STEP 7 -- CORROSION DESIGN (75-YR SACRIFICIAL THICKNESS)
A3: corrosion.py -- galvanizing + sacrificial steel -> t_corroded feeding Step 6. Doc Section 7.
A5: Inputs
A6: Nominal wall thickness, t_nominal (Step 3) | D6: ='3-Sizing'!$D$11 | E6: mm
A7: Zinc (HDG) thickness, t_zn | D7: 100 | E7: um
A8: Zinc corrosion rate, r_zn | D8: 4 | E8: um/yr
A9: Bare-steel corrosion rate, r_s | D9: 20 | E9: um/yr
A10: Design life | D10: 75 | E10: yr
A11: Both faces corrode (open/vented section)? | D11: No
A12: Soil resistivity | D12: 3000 | E12: ohm-cm
A13: Soil pH | D13: 7 | E13: -
A15: Calculated
A16: Zinc life | D16: =$D$7/$D$8 | E16: yr
A17: Remaining design life after zinc consumed | D17: =MAX($D$10-$D$16,0) | E17: yr
A18: Sacrificial thickness, t_sac | D18: =$D$9*$D$17/1000 | E18: mm
A19: Corroded wall thickness, t_corroded | D19: =$D$6-$D$18*IF($D$11="Yes",2,1) | E19: mm
A20: Corrosivity classification | D20: =IF(OR($D$12<1000,$D$13<5.5),"severely corrosive -- cathodic protection or epoxy required; confirm helical piles permitted per AC358",IF(AND($D$12>=2000,$D$13>=5.5,$D$13<=10,$D$10<=50),"non-aggressive (screening basis)","moderately corrosive design case -- explicit sacrificial-thickness calc required")) | E20: -

Sheet 8-Connection
A1: STEP 8 -- POLE-TO-PILE CONNECTION DESIGN
A3: connection.py -- anchor bolts (combined tension+standoff bending), fillet weld, torsional slip. Doc Section 8.
A5: Demands (Step 1 strength case)
A6: M (overturning moment) | D6: ='1-Loads'!$D$39 | E6: kN*m
A7: V (shear) | D7: ='1-Loads'!$D$38 | E7: kN
A8: Tz (torsion, single-arm poles only) | D8: ='1-Loads'!$D$41 | E8: kN*m
A9: D_shaft (Step 3) | D9: ='3-Sizing'!$D$10 | E9: m
A10: Net uplift on bolt group, P_uplift | D10: 0 | E10: kN
A12: 8.1 Anchor bolt group geometry
A13: Number of bolts, n | D13: 4 | E13: -
A14: Bolt circle radius, r | D14: 0.2 | E14: m
A15: Bolt tensile stress area, Ab (per bolt) | D15: 0.000314 | E15: m^2
A16: Bolt Fu (e.g. F1554 Gr55) | D16: 520000 | E16: kPa
A17: Nominal bolt diameter (thread-root modulus not modeled -- see note) | D17: 0.0254 | E17: m
A18: NOTE: bolt_section_modulus_m3 uses the NOMINAL diameter as a stand-in for the (smaller) thread-root diameter -- this overestimates the section modulus and therefore UNDERESTIMATES bending stress. Acceptable for a preliminary screen only; replace with the manufacturer's thread-root modulus before final design.
A19: Leveling-nut standoff | D19: 0 | E19: m
A20: phi_t (bolt tension, AISC 360 J3) | D20: 0.75 | E20: -
A22: Sum(ci^2) -- worst-case bending axis, n bolts evenly spaced on the circle
A23: Bolt i | D23: ci^2 term (0 if i>=n)
A24: 0 | D24: =IF(0<$D$13,($D$14*COS(2*PI()*0/$D$13))^2,0)
A25: 1 | D25: =IF(1<$D$13,($D$14*COS(2*PI()*1/$D$13))^2,0)
A26: 2 | D26: =IF(2<$D$13,($D$14*COS(2*PI()*2/$D$13))^2,0)
A27: 3 | D27: =IF(3<$D$13,($D$14*COS(2*PI()*3/$D$13))^2,0)
A28: 4 | D28: =IF(4<$D$13,($D$14*COS(2*PI()*4/$D$13))^2,0)
A29: 5 | D29: =IF(5<$D$13,($D$14*COS(2*PI()*5/$D$13))^2,0)
A30: 6 | D30: =IF(6<$D$13,($D$14*COS(2*PI()*6/$D$13))^2,0)
A31: 7 | D31: =IF(7<$D$13,($D$14*COS(2*PI()*7/$D$13))^2,0)
A32: 8 | D32: =IF(8<$D$13,($D$14*COS(2*PI()*8/$D$13))^2,0)
A33: 9 | D33: =IF(9<$D$13,($D$14*COS(2*PI()*9/$D$13))^2,0)
A34: 10 | D34: =IF(10<$D$13,($D$14*COS(2*PI()*10/$D$13))^2,0)
A35: 11 | D35: =IF(11<$D$13,($D$14*COS(2*PI()*11/$D$13))^2,0)
A36: Sum(ci^2) | D36: =SUM($D$24:$D$35) | E36: m^2
A38: 8.2 Combined bolt tension + standoff-bending check
A39: Bolt tension demand, T_bolt = M*c_max/Sum(ci^2) + P_uplift/n | D39: =$D$6*$D$14/$D$36+$D$10/$D$13 | E39: kN
A40: Tension stress, sigma_tension = T_bolt/Ab | D40: =$D$39/$D$15 | E40: kPa
A41: Standoff bending moment, M_b (0 if standoff <= bolt diam) | D41: =IF($D$19<=$D$17,0,($D$7/$D$13)*$D$19/2) | E41: kN*m
A42: Bolt section modulus, Z_bolt (solid shank) | D42: =PI()*$D$17^3/32 | E42: m^3
A43: Bending stress, sigma_bending | D43: =IF($D$42>0,$D$41/$D$42,0) | E43: kPa
A44: Combined stress, sigma_total | D44: =$D$40+$D$43 | E44: kPa
A45: Capacity, sigma_capacity = phi_t*0.75*Fu | D45: =$D$20*0.75*$D$16 | E45: kPa
...

Sheet 9-Torque
A1: STEP 9 -- INSTALLATION TORQUE SPECIFICATION
A3: torque.py -- dual termination criteria (torque AND depth); torque never waives depth. Doc Section 9.
A5: Inputs
A6: FS, axial (design basis) | D6: 2 | E6: -
A7: Compression demand, P_max (Step 4) | D7: ='4-Axial'!$D$46 | E7: kN
A8: Frost-uplift demand, T_frost (Step 4) | D8: ='4-Axial'!$D$37 | E8: kN
A9: Torque coefficient, Kt [ASSUMED -- validate: AC358 report or site load test] | D9: 7 | E9: 1/m
A10: Kt source | D10: ASSUMED -- validate before production
A11: Torque rating, T_rated | D11: 15 | E11: kN*m
A12: Anticipated/measured average torque, T_avg | D12: 6.5 | E12: kN*m
A13: Minimum tip depth required (Steps 3/5) | D13: ='3-Sizing'!$D$25 | E13: m
A14: Installed tip depth (as-built override) | E14: m
A15: Installed tip depth (used) | D15: =IF($D$14="",$D$13,$D$14) | E15: m
A17: Calculated -- doc eq. 9.2(1)
A18: Required ultimate axial capacity, P_req | D18: =MAX($D$6*$D$7,$D$6*$D$8) | E18: kN
A19: Minimum termination torque, T_min | D19: =$D$18/$D$9 | E19: kN*m
A21: Dual termination criteria -- ALL THREE must be satisfied (doc Section 9.2)
A22: (1) T_avg >= T_min? | D22: =$D$12>=$D$19
A23: (2) Installed depth >= minimum? (torque cannot waive this) | D23: =$D$15>=$D$13
A24: (3) T_avg <= T_rated (never exceed rating)? | D24: =$D$12<=$D$11
A25: Step 9 termination criteria -- ALL PASS? | D25: =AND($D$22,$D$23,$D$24)

Sheet 10-QAQC
A1: STEP 10 -- QA/QC AND LOAD-TEST TRIGGERS
A3: qaqc.py -- rule engine reading flags from every prior step. Doc Section 10.2. Not a calculation -- a trigger table for ASTM D1143/D3689/D3966.
A5: Trigger inputs (mostly linked from prior steps)
A6: Kt established by AC358 report? | D6: ='9-Torque'!$D$10="AC358 report"
A7: Frost-uplift design relies on assumed tau_ad/sleeve performance? | D7: Yes
A8: (as boolean) | D8: =$D$7="Yes" | E8: -
A9: p-y params from lab/CPT (Step 2)? | D9: ='2-Geotech'!$D$27 | E9: -
A10: Service deflection / limit ratio (Step 5b) | D10: ='5b-pySolver'!$D$3598 | E10: -
A11: Number of production piles | D11: 40 | E11: -
A12: Variable or unfamiliar soils across the site? | D12: No
A13: Owner/code official requires a load test? | D13: No
A14: Trigger evaluation -- doc Section 10.2
A15: D1143/D3689 triggered? (Kt not AC358-verified) | D15: =NOT($D$6)
A16: D3689 triggered? (frost-uplift relies on assumed values) | D16: =$D$8
A17: D3966 triggered? (low lateral margin OR p-y not lab/CPT) | D17: =OR($D$10>0.75,NOT($D$9))
A18: D3689+D3966 triggered? (>50 piles OR variable soils) | D18: =OR($D$11>50,$D$12="Yes")
A19: Owner/code-official-directed test triggered? | D19: =$D$13="Yes"
A20: ANY load test triggered? | D20: =OR($D$15,$D$16,$D$17,$D$18,$D$19)
A22: Baseline QA items (always applicable)
A23: [ ] Mill certs for shaft/helix steel and HDG on file
A24: [ ] AC358 evaluation report (or equivalent product data) on file
A25: [ ] Calibrated torque indicator certificate <= 12 months old
A26: [ ] Installation logs (torque-vs-depth, per pile) reviewed and signed by the engineer
A27: [ ] Anchor-bolt template verification completed before pole delivery

Sheet Summary
A1: PASS/FAIL ROLLUP -- ALL STEPS
A3: Pulls the governing pass/fail cell from each step sheet. GREEN = pass, RED = fail. This does not replace engineer review of every assumption cell (pale orange) on each sheet.
A5: Step | B5: Check | C5: Result | D5: Notes
A6: 3 | B6: Embedment screens (frost clearance + deep-foundation mode) | C6: ='3-Sizing'!$D$32
A7: 4 | B7: Axial compression, FS>=2.0 | C7: ='4-Axial'!$D$51
A8: 4 | B8: Axial tension vs. frost uplift, FS>=2.0 | C8: ='4-Axial'!$D$55
A9: 5a | B9: Broms preliminary lateral, FS>=2.0 | C9: ='5a-Broms'!$D$86 | D9: Cross-check only, doc 5.2
A10: 5b | B10: p-y serviceability (deflection + rotation) | C10: ='5b-pySolver'!$D$3597
A11: 5b | B11: p-y pushover, FS>=2.0 | C11: ='5b-pySolver'!$F$3604 | D11: lambda_ult = see 5b-pySolver!'5b-pySolver'!$F$3603
A12: 6 | B12: Section compactness | C12: ='6-Structural'!$D$16
A13: 6 | B13: H1 combined axial+flexure | C13: ='6-Structural'!$D$29
A14: 6 | B14: Shear | C14: ='6-Structural'!$D$35
A15: 6 | B15: Installation torsion cap | C15: ='6-Structural'!$D$47
A16: 8 | B16: Bolt combined tension+bending | C16: ='8-Connection'!$D$46 | D16: Uses nominal-diameter Z_bolt -- see Step 8 note
A17: 8 | B17: Fillet weld | C17: ='8-Connection'!$D$58
A18: 8 | B18: Torsional slip (single-arm poles) | C18: ='8-Connection'!$D$63
A19: 9 | B19: Installation torque -- dual termination criteria | C19: ='9-Torque'!$D$25
A21: Overall
B22: ALL CHECKS PASS? | C22: =AND(C6:C19)
A24: Step 10 -- QA/QC
B25: Any full-scale load test triggered? | C25: ='10-QAQC'!$D$20 | D25: See 10-QAQC for which test(s) and why.
